Workbook
Name AE: Données!$B$11:$B$18
Name AL: Données!$C$11:$C$14
Name AN: Données!$D$11:$D$13
Name AO: Données!$E$11:$E$16
Name AR: Données!$F$11:$F$21
Name AS: Données!$G$11
Name AU: Données!$H$11:$H$22
Name AW: Données!$I$11
Name AZ: Données!$J$11
Name BB: Données!$K$11
Name BD: Données!$L$11:$L$12
Name BE: Données!$M$11:$M$15
Name BG: Données!$N$11
Name BH: Données!$O$11:$O$12
Name BJ: Données!$P$11
Name BM: Données!$Q$11:$Q$12
Name BN: Données!$R$11:$R$12
Name BR: Données!$S$11:$S$24
Name BS: Données!$T$11:$T$12
Name BZ: Données!$U$11
Name CA: Données!$V$11:$V$27
Name CG: Données!$W$11
Name CH: Données!$X$11
Name CI: Données!$Y$11
Name CL: Données!$Z$11:$Z$20
Name CM: Données!$AA$11:$AA$13
Name CN: Données!$AB$11:$AB$26
Name CO: Données!$AC$11:$AC$16
Name CR: Données!$AD$11:$AD$14
Name CS: Données!$AE$11:$AE$12
Name CU: Données!$AF$11:$AF$15
Name CV: Données!$AG$11
Name CY: Données!$AH$11:$AH$16
Name DE: Données!$AI$11:$AI$23
Name DJ: Données!$AJ$11
Name DK: Données!$AK$11:$AK$17
Name DM: Données!$AL$11:$AL$12
Name DO: Données!$AM$11:$AM$16
Name DZ: Données!$AN$11:$AN$20
Name EC: Données!$AO$11:$AO$16
Name EE: Données!$AP$11:$AP$12
Name EG: Données!$AQ$11:$AQ$14
Name ES: Données!$AR$11:$AR$26
Name FI: Données!$AS$11:$AS$21
Name FISCALISE: [1]Feuil1!$IS$1:$IS$2
Name FJ: Données!$AT$11:$AT$15
Name FM: Données!$AU$11
Name FO: Données!$AV$11:$AV$12
Name FR: Données!$AW$11:$AW$23
Name GA: Données!$AX$11:$AX$14
Name GB: Données!$AY$11:$AY$32
Name GE: Données!$AZ$11:$AZ$13
Name GF: Données!$BA$11
Name GH: Données!$BB$11:$BB$12
Name GI: Données!$BC$11
Name GL: Données!$BD$11:$BD$14
Name GM: Données!$BE$11
Name GN: Données!$BF$11:$BF$12
Name GP: Données!$BG$11:$BG$12
Name GQ: Données!$BH$11:$BH$13

Sheet Supplier's Listing
A1: =Données!H154 -> Visual or Sample n° | B1: =Données!H155 -> Supplier's reference | C1: =Données!H156 -> Supplier's designation | D1: =Données!H157 -> Noz designation | E1: =Données!H158 -> Colour(s) | F1: =Données!H159 -> Measure units | G1: =Données!H160 -> Brand/License | H1: =Données!H161 -> BIUB or BBD* (dd/mm/yyyy) | I1: =Données!H162 -> Untaxed (Wine) | J1: =Données!H163 -> Qty available | K1: =Données!H164 -> Wholesale Price | L1: =Données!H165 -> Clearance Price | M1: =Données!H166 -> Retail price | N1: =Données!H167 -> Packing details | O1: =Données!H168 -> Nb packets / pallet | P1: =Données!H169 -> Number of pallets

Sheet Batch information
A1: en | B1: =Données!H95 -> Update 13.04.2024 | O1: =Données!I95 -> Update 13.04.2024
A2: =Données!H76 -> SUPPLIER NAME | H2: =Données!H94 -> ADDITIONAL INFORMATION | O2: =IF(ISBLANK(C2),"",C2)
H3: 1. Supplier status 2. Description of the company
A4: =Données!H77 -> ORIGIN OF THE LOT | O4: =IFERROR(_xlfn.IFNA(_xlfn.IFNA(VLOOKUP(C4,Données!H63:I74,2,FALSE),VLOOKUP(C4,Données!B63:I74,8,FALSE)),VLOOKUP(C4,Données!A63:I74,9,FALSE)),"")
A6: =Données!H78 -> SUPPLIER'S EXPECTATION | O6: =IFERROR(_xlfn.IFNA(_xlfn.IFNA(VLOOKUP(C6,Données!H150:I152,2,FALSE),VLOOKUP(C6,Données!B45:I150,8,FALSE)),VLOOKUP(C6,Données!A150:I152,9,FALSE)),"")
A8: =Données!H79 -> YEAR OF THE STOCK | O8: =IF(ISBLANK(C8),"",C8)
A10: =Données!H80 -> BRAND(S) / LICENSE(S) | O10: =IFERROR(_xlfn.IFNA(_xlfn.IFNA(VLOOKUP(C10,Données!H129:I131,2,FALSE),VLOOKUP(C10,Données!B129:I131,8,FALSE)),VLOOKUP(C10,Données!A129:I131,9,FALSE)),"")
H11: 3. Origin of the batch 4. Need
A12: =Données!H81 -> SAMPLES | O12: =IFERROR(_xlfn.IFNA(_xlfn.IFNA(VLOOKUP(C12,Données!H139:I140,2,FALSE),VLOOKUP(C12,Données!B139:I140,8,FALSE)),VLOOKUP(C12,Données!A139:I140,9,FALSE)),"")
A14: =Données!H82 -> TRANSLATION NEEDED | O14: =IFERROR(_xlfn.IFNA(_xlfn.IFNA(VLOOKUP(C14,Données!H139:I140,2,FALSE),VLOOKUP(C14,Données!B139:I140,8,FALSE)),VLOOKUP(C14,Données!A139:I140,9,FALSE)),"")
A16: =Données!H83 -> CONCURRENCE | O16: =IFERROR(_xlfn.IFNA(_xlfn.IFNA(VLOOKUP(C16,Données!H139:I140,2,FALSE),VLOOKUP(C16,Données!B139:I140,8,FALSE)),VLOOKUP(C16,Données!A139:I140,9,FALSE)),"")
A18: =Données!H84 -> IF CONCURRENCE | O18: =IF(ISBLANK(C18),"",C18)
A20: =Données!H85 -> PACKING DETAILS | O20: =IFERROR(_xlfn.IFNA(_xlfn.IFNA(VLOOKUP(C20,Données!H104:I106,2,FALSE),VLOOKUP(C20,Données!B104:I106,8,FALSE)),VLOOKUP(C20,Données!A104:I106,9,FALSE)),"")
H21: 5. Our response: 6. Type of offer (global, global a la ligne, partial, etc.):
A22: =Données!H96 -> PACKAGE | O22: =IFERROR(_xlfn.IFNA(_xlfn.IFNA(VLOOKUP(C22,Données!H139:I140,2,FALSE),VLOOKUP(C22,Données!B139:I140,8,FALSE)),VLOOKUP(C22,Données!A139:I140,9,FALSE)),"")
A24: =Données!H86 -> NUMBER OF PALLETS | O24: =IF(ISBLANK(C24),"",C24)
A26: =Données!H87 -> PALLETIZED | O26: =IFERROR(_xlfn.IFNA(_xlfn.IFNA(VLOOKUP(C26,Données!H139:I140,2,FALSE),VLOOKUP(C26,Données!B139:I140,8,FALSE)),VLOOKUP(C26,Données!A139:I140,9,FALSE)),"")
A28: =Données!H88 -> IF PALETISE | O28: =IF(ISBLANK(C28),"",C28)
A30: =Données!H89 -> SHARED ORDER | O30: =IFERROR(_xlfn.IFNA(_xlfn.IFNA(VLOOKUP(C30,Données!H146:I148,2,FALSE),VLOOKUP(C30,Données!B146:I148,8,FALSE)),VLOOKUP(C30,Données!A146:I148,9,FALSE)),"")
A32: =Données!H90 -> CITY & COUNTRY LOCATION | H32: 7. Extras + other details/restrictions/packaging about the batch | O32: =IF(ISBLANK(C32),"",C32)
A34: =Données!H91 -> ZIP CODE | O34: =IF(ISBLANK(C34),"",C34)
A36: =Données!H92 -> REPLY NOTICE | O36: =IFERROR(_xlfn.IFNA(_xlfn.IFNA(VLOOKUP(C36,Données!H142:I144,2,FALSE),VLOOKUP(C36,Données!B142:I144,8,FALSE)),VLOOKUP(C36,Données!A142:I144,9,FALSE)),"")
A39: =Données!H93 -> Please Note : Supplier = Previous Order Placed / Prospect : No Order Yet

Sheet Données
C2: No | E2: Mono produits | I2: Manufacturer | J2: Large retailers | K2: Order Cancellation | L2: Supplier | O2: No | U2: Global
C3: Yes / Blank | E3: Mixed | I3: Wholesaler | J3: Multibrand stores | K3: Second choice / Low quality | L3: Prospect | O3: Yes / Unregistered | U3: Global / Ref | W3: Supplier Warehouse | Z3: Yes | AB3: Appel Offre | AD3: A la Référence | AG3: Bulk
C4: Yes / Pictures | E4: Bulk | I4: Trader | J4: Specialized stores | K4: Bankruptcy | O4: Yes / Registered | U4: Best Price | W4: On board | Z4: No | AB4: Habituel | AD4: Au Volume | AG4: Mixed
C5: Yes / With logo | I5: Distributor | J5: Online stores | K5: Warehouse / Unsold stock | W5: Port | AB5: Urgent | AD5: Non partageable | AG5: Mono produits
C6: Yes / Translation needed | I6: Retailer | K6: End of lines / collections | W6: Forwarder Warehouse
I7: Importer | K7: Production surplus | W7: Customer Warehouse
K8: Return of unsold goods
K9: Short BBD
B10: AE | C10: AL | D10: AN | E10: AO | F10: AR | G10: AS | H10: AU | I10: AW | J10: AZ | K10: BB | L10: BD | M10: BE | N10: BG | O10: BH | P10: BJ | Q10: BM | R10: BN | S10: BR | T10: BS | U10: BZ | V10: CA | W10: CG | X10: CH | Y10: CI | Z10: CL | AA10: CM | AB10: CN | AC10: CO | AD10: CR | AE10: CS | AF10: CU | AG10: CV | AH10: CY | AI10: DE | AJ10: DJ | AK10: DK | AL10: DM | AM10: DO | AN10: DZ | AO10: EC | AP10: EE | AQ10: EG | AR10: ES | AS10: FI | AT10: FJ | AU10: FM | AV10: FO | AW10: FR | AX10: GA | AY10: GB | AZ10: GE | BA10: GF | BB10: GH | BC10: GI | BD10: GL | BE10: GM | BF10: GN | BG10: GP | BH10: GQ | BI10: GR | BJ10: GT | BK10: GU | BL10: GW | BM10: GY | BN10: HK | BO10: HN | BP10: HR | BQ10: HT | BR10: ID | BS10: IE | BT10: IL | BU10: IN | BV10: IQ | BW10: IR | BX10: IS | BY10: IT | BZ10: JM | CA10: JO | CB10: JP | CC10: KE | CD10: KH | CE10: KI | CF10: KM | CG10: KN | CH10: KP | CI10: KR | CJ10: KW | CK10: KY | CL10: LB | CM10: LC | CN10: LK | CO10: LR | CP10: LT | CQ10: LV | CR10: LY | CS10: MA | CT10: MC | CU10: MG | CV10: MM | CW10: MO | CX10: MP | CY10: MQ | CZ10: MR | DA10: MS | DB10: MT | DC10: MU | DD10: MX | DE10: MY | DF10: MZ | DG10: NA | DH10: NC | DI10: NG | DJ10: NI | DK10: NL | DL10: NO | DM10: NR | DN10: NZ | DO10: PA | DP10: PE | DQ10: PF | DR10: PG | DS10: PH | DT10: PK | DU10: PL | DV10: PM | DW10: PR | DX10: PT | DY10: QA | DZ10: RE | EA10: RO | EB10: RU | EC10: SA | ED10: SB | EE10: SC | EF10: SD | EG10: SE | EH10: SG | EI10: SH | EJ10: SI | EK10: SL | EL10: SN | EM10: SO | EN10: SR | EO10: ST | EP10: SV | EQ10: SY | ER10: TC | ES10: TG | ET10: TH | EU10: TN | EV10: TO | EW10: TR | EX10: TT | EY10: TV | EZ10: TW | FA10: TZ | FB10: UA | FC10: US | FD10: UY | FE10: VC | FF10: VE | FG10: VI | FH10: VN | FI10: VU | FJ10: WS | FK10: YE | FL10: ZA | FM10: ZR
B11: Ajman | C11: Durres (Durazzo) | D11: Kralendijk, Bonaire | E11: Cabinda | F11: Bahia Blanca | G11: Pago Pago | H11: Adelaide | I11: Oranjestad | J11: Baku | K11: Bridgetown | L11: Chittagong | M11: Antwerp | N11: Varna | O11: Mina Salman | P11: Cotonou | Q11: Hamilton | R11: Kuala Belait | S11: Belem | T11: Freeport | U11: Belize City | V11: Becancour | W11: Pointe Noire | X11: Basel | Y11: Abidjan | Z11: Antofagasta | AA11: Douala | AB11: Dalian | AC11: Barranquilla | AD11: Caldera | AE11: Bar | AF11: Havana | AG11: Porto Grande | AH11: Akrotiri | AI11: Brake | AJ11: Djibouti | AK11: Aarhus | AL11: Portsmouth | AM11: Barahona | AN11: Algiers | AO11: Esmeraldas | AP11: Pärnu | AQ11: Alexandria | AR11: Aviles | AS11: Hamina | AT11: Labasa (Lambasa) | AU11: Pohnpei (Ex Ponape) | AV11: Klaksvik | AW11: Bordeaux | AX11: Cap Lopez | AY11: Aberdeen | AZ11: Batumi | BA11: Cayenne | BB11: Takoradi | BC11: Gibraltar | BD11: Holsteinsborg (Sisimiut) | BE11: Banjul | BF11: Conakry | BG11: Gustavia | BH11: Bata | BI11: Eleusis | BJ11: Champerico | BK11: Apra (Agana) | BL11: Bissau | BM11: Georgetown | BN11: Hong Kong | BO11: La Ceiba | BP11: Dubrovnik | BQ11: Port Au Prince | BR11: Cilacap, Java(Tanjung Intan) | BS11: Arklow | BT11: Ashdod | BU11: Bombay (Mumbai) | BV11: Basra | BW11: Abadan | BX11: Akureyri | BY11: Augusta | BZ11: Kingston | CA11: Aqaba (El Akaba) | CB11: Akita | CC11: Lamu | CD11: Kompongsom (also known as:) | CE11: Betio (Tarawa) | CF11: Moroni | CG11: Basseterre | CH11: Chongjin | CI11: Busan (Pusan) | CJ11: Mina al Ahmadi | CK11: Georgetown, Grand Cayman | CL11: Beirut | CM11: Castries (St Lucia) | CN11: Colombo | CO11: Buchanan | CP11: Klaipeda (includes sixsubports) | CQ11: Liepaja | CR11: Bingazi (Benghazi) | CS11: Agadir | CT11: Monaco | CU11: Antsiranana (Diego Suarez) | CV11: Bassein | CW11: Macau (Macao, Aomen) | CX11: Saipan | CY11: Fort de France | CZ11: Nouadhibou | DA11: Plymouth | DB11: Valletta | DC11: Port Louis | DD11: Acapulco | DE11: Bintulu, Sarawak | DF11: Beira | DG11: Luderitz | DH11: Noumea | DI11: Calabar | DJ11: Bluefields | DK11: Amsterdam | DL11: Bergen | DM11: Nauru Island | DN11: (Dunedin, Port Chalmers, Ravensbourne) | DO11: Colon | DP11: Callao | DQ11: Papeete | DR11: Kieta | DS11: Batangas | DT11: Karachi | DU11: Gdansk | DV11: St Pierre | DW11: Guanica Harbour | DX11: Aveiro | DY11: Doha | DZ11: Port Reunion (Pointe des Galets) | EA11: Braila | EB11: Kholmsk | EC11: Dammam | ED11: Honiara | EE11: Port Victoria | EF11: Port Sudan | EG11: Gavle | EH11: Singapore | EI11: Georgetown | EJ11: Izola | EK11: Freetown | EL11: Dakar | EM11: Berbera | EN11: Moengo | EO11: Santo Antonio | EP11: Acajutla | EQ11: Baniyas | ER11: Grand Turk Island | ES11: Kpeme | ET11: Bangkok | EU11: Bizerte | EV11: Neiafu | EW11: Derince | EX11: Point Fortin | EY11: Funafuti | EZ11: Hualien | FA11: Dar Es Salaam | FB11: Berdyansk | FC11: Anacortes | FD11: Fray Bentos | FE11: Kingstown | FF11: Bajo Grande Refinery | FG11: Charlotte Amalie,St. Thomas | FH11: Danang | FI11: Port Vila | FJ11: Apia | FK11: Aden | FL11: Cape Town | FM11: Banana
B12: Das Island | C12: Sarande | D12: Philipsburg | E12: Lobito | F12: Buenos Aires | H12: Brisbane | L12: Mongla | M12: Brussels (Bruxelles) | O12: Sitra | Q12: St Georges | R12: Muara | S12: Fortaleza | T12: Nassau | V12: Churchill | Z12: Arica | AA12: Kribi | AB12: Fuzhou | AC12: Buenaventura | AD12: Puerto Limon | AE12: Kotor | AF12: Manzanillo | AH12: Famagusta | AI12: Bremen | AK12: Esbjerg | AL12: Roseau | AM12: La Romana | AN12: Annaba (Ex Bone) | AO12: Guayaquil | AP12: Tallinn | AQ12: Damietta | AR12: Barcelona | AS12: Helsinki | AT12: Lautoka | AV12: Torshavn | AW12: Boulogne Sur Mer | AX12: Libreville | AY12: Belfast | AZ12: Poti | BB12: Tema | BD12: Nanortalik | BF12: Port Kamsar | BG12: Pointe-a-Pitre | BH12: Ceiba Marine Terminal | BI12: Iraklion (Heraklion) | BJ12: Puerto Barrios | BM12: New Amsterdam | BO12: Puerto Castilla | BP12: Omisalj | BR12: Cirebon, Java | BS12: Cork | BT12: Ashkelon | BU12: Calcutta (Kolkata) | BV12: Khor al Zubair | BW12: Bandar Abbas | BX12: Hafnarfjordur (Straumsvik) | BY12: Bagnoli | BZ12: Montego Bay | CB12: Amagasaki | CC12: Mombasa | CD12: Phnom Penh | CF12: Mutsamudu | CH12: Haeju | CI12: Chinhae | CJ12: Mina Saud | CL12: Chekka | CM12: Vieux Fort | CN12: Jaffna | CO12: Greenville | CQ12: Ventspils | CR12: Derna | CS12: Casablanca | CU12: Majunga (Mahajanga) | CV12: Moulmein | CZ12: Nouakchott | DD12: Coatzacoalcos | DE12: Kota Kinabalu, Sabah | DF12: Inhambane | DG12: Walvis Bay | DH12: Thio | DI12: Lagos | DJ12: Corinto | DK12: Delfzijl | DL12: Drammen | DN12: Auckland Otago Harbour | DO12: Cristobal | DP12: Chimbote | DR12: Lae | DS12: Cagayan de Oro, Mindanao | DT12: Muhammad Bin Qasim | DU12: Gdynia | DW12: Guayanilla | DX12: Leixoes | DY12: Halul Island | EA12: Constantza | EB12: Murmansk | EC12: Dhuba | ED12: Noro, New Georgia | EG12: Gothenburg (Goteborg) | EI12: Jamestown | EJ12: Koper | EK12: Pepel | EM12: Kismayu | EN12: Nieuw Nickerie | EO12: Sao Tome | EP12: Cutuco | ER12: Providenciales | ES12: Lome | ET12: Laem Chabang | EU12: Gabes | EV12: Nukualofa | EW12: Dikili | EX12: Point Lisas | EZ12: Kaohsiung | FA12: Kilwa Masoko | FB12: Kherson | FC12: Ashtabula | FD12: Montevideo | FF12: Cumana (Puerto Sucre | FG12: Christiansted, St. Croix | FH12: Haiphong | FI12: Santo | FK12: Hodeidah | FL12: Durban | FM12: Boma
B13: Dubai (Port Rashid) | C13: Shengjjin | D13: Willemstad | E13: Luanda | F13: Comodoro Rivadavia | H13: Cairns | M13: Ghent | S13: Imbituba | V13: Fraser River Port (Port of New Westminster) | Z13: Chanaral | AA13: Tiko | AB13: Guangzhou | AC13: Cartagena | AF13: Matanzas | AH13: Larnaca | AI13: Bremerhaven | AK13: Fredericia | AM13: Puerto Plata | AN13: Arzew | AO13: La Libertad | AQ13: Port Said | AR13: Bilbao | AS13: Kokkola | AT13: Levuka | AW13: Cherbourg | AX13: Owendo | AY13: Bristol | AZ13: Sukhumi | BD13: Narsarsuaq | BH13: Malabo (Rey Malabo) | BI13: Kavala | BJ13: Santo Tomas De Castilla | BO13: Puerto Cortes | BP13: Ploce | BR13: Jakarta, Java (Tanjung Priok) | BS13: Drogheda | BT13: Eilat | BU13: Chennai (Madras) | BV13: Umm Qasr | BW13: Bandar Anzali | BX13: Isafjordur | BY13: Bari | BZ13: Ocho Rios | CB13: Chiba | CH13: Nampo | CI13: Inchon | CJ13: Shuwaikh | CL13: Selaata | CN13: Trincomalee | CO13: Monrovia | CQ13: Riga | CR13: Marsa El Brega | CS13: El Jadida | CU13: Toamasina (Tamatave) | CV13: Yangon | DD13: Guaymas | DE13: Kuantan (Tanjong Gelang) | DF13: Maputo | DI13: Onne | DJ13: El Bluff | DK13: Dordrecht | DL13: Grenland Harbour (Rafnes, Heroya) | DN13: Tauranga | DO13: Vacamonte | DP13: Ilo | DR13: Madang | DS13: Cebu | DU13: Kolobrzeg | DW13: Las Mareas | DX13: Lisbon | DY13: Ras Laffan | EA13: Mangalia | EB13: Nakhodka | EC13: Gizan | ED13: Viru Harbour | EG13: Halmstad | EJ13: Piran | EM13: Merca | EN13: Paramaribo | ET13: Pattani | EU13: La Goulette | EV13: Pangai | EW13: Gemlik | EX13: Pointe a Pierre | EZ13: Keelung (Chilung) | FA13: Lindi | FB13: Odessa | FC13: Baltimore | FD13: Nueva Palmira | FF13: La Guaira | FG13: Limetree Bay | FH13: Ho Chi Minh City | FK13: Mokha | FL13: Mossel Bay
B14: Fujairah | C14: Vlore (Vlora, Vlone) | E14: Namibe | F14: Concepcion del Uruguay | H14: Darwin | M14: Liege | S14: Itajai | V14: Halifax | Z14: Iquique | AB14: Haikou | AC14: Puerto Bolivar | AF14: Nuevitas | AH14: Limassol | AI14: Duisburg | AK14: Frederikshavn | AM14: Rio Haina | AN14: Bejaia (Ex Bougie) | AO14: Manta | AQ14: Suez (Al Suweis) | AR14: Cadiz | AS14: Kotka | AT14: Savu Savu | AW14: Dunkerque | AX14: Port Gentil | AY14: Dover | BD14: Nuuk (Godthaab) | BI14: Patras | BO14: San Lorenzo | BP14: Pula | BR14: Kupang, Timor | BS14: Dublin | BT14: Hadera | BU14: Cochin | BW14: Bandar Mahshahr | BX14: Keflavik | BY14: Brindisi | BZ14: Port Antonio | CB14: Hachinohe | CH14: Wonsan | CI14: Masan | CL14: Sidon | CR14: Misurata (Qasr Ahmed) | CS14: Kenitra | CU14: Tulear (Toliara) | DD14: La Paz | DE14: Kuching, Sarawak | DF14: Nacala | DI14: Port Harcourt | DJ14: Puerto Cabezas | DK14: Eemshaven | DL14: Hammerfest | DN14: Wellington | DP14: Matarani | DR14: Port Moresby | DS14: Davao, Mindanao | DU14: Swinoujscie | DW14: Ponce | DX14: Portimao | DY14: Umm Said (Mesaieed) | EA14: Sulina | EB14: Novorossiysk | EC14: Jeddah | ED14: Yandina, Pavuvu Island | EG14: Kalmar | EM14: Mogadishu | EN14: Paranam | ET14: Phuket | EU14: Sfax | EW14: Hopa, Artvin | EX14: Scarborough | EZ14: Suao | FA14: Mtwara | FB14: Reni | FC14: Baton Rouge | FD14: Paysandu | FF14: La Salina | FH14: Hon Gay | FK14: Mukalla | FL14: Port Elizabeth
B15: Jebel Dhanna/ | E15: Porto Amboim | F15: Mar del Plata | H15: Devonport | M15: Zeebrugge | S15: Manaus | V15: Hamilton | Z15: Puerto Montt | AB15: Lianyungang | AC15: Tumaco | AF15: Santiago de Cuba | AH15: Paphos | AI15: Dusseldorf | AK15: Grenaa | AM15: San Pedro de | AN15: Dellys | AO15: Puerto Bolivar | AR15: Cartagena | AS15: Loviisa | AT15: Suva | AW15: La Rochelle-Pallice | AY15: Falmouth | BI15: Piraeus | BO15: Tela | BP15: Rijeka Bakar | BR15: Palembang, Sumatra | BS15: Foynes (Shannon Foynes Port) | BT15: Haifa | BU15: Kandla | BW15: Bushehr | BX15: Reykjavik | BY15: Gela | BZ15: Port Esquivel | CB15: Hakodate, Hokkaido | CI15: Mokpo | CL15: Tripoli | CR15: Ras Lanuf | CS15: Mohammedia | DD15: Lazaro Cardenas | DE15: Kudat, Sabah | DF15: Pemba | DI15: Sapele | DJ15: Puerto Sandino | DK15: Groningen | DL15: Harstad | DP15: Paita | DR15: Rabaul | DS15: Iligan, Mindanao | DU15: Szczecin | DW15: San Juan | DX15: Setubal | EB15: St Petersburg | EC15: Jubail | EG15: Karlshamn | EN15: Wageningen | ET15: Sattahip | EU15: Sousse | EW15: Iskenderun, Hatay | EX15: Spain | EZ15: Taichung | FA15: Pangani | FB15: Sevastopol | FC15: Beaumont | FF15: Maracaibo | FH15: Nha Trang | FL15: Richards Bay
B16: Khor Fakkan | E16: Soyo | F16: Necochea | H16: Fremantle | S16: Navegantes | V16: Montreal | Z16: Punta Arenas | AB16: Nantong | AC16: Turbo | AH16: Vassiliko | AI16: Emden | AK16: Odense | AM16: Santo Domingo | AN16: Ghazaouet | AO16: San Lorenzo | AR16: Castellon | AS16: Oulu | AW16: Le Havre | AY16: Felixstowe | BI16: Thessaloniki | BP16: Sibenik | BR16: Semarang, Java (Tanjung Emas) | BS16: Galway | BU16: Nhava Sheva (Jawaharlal Nehru) | BW16: Imam Khomeini | BX16: Vestmannaeyjar | BY16: Genoa | BZ16: Rocky Point | CB16: Higashiharima | CI16: Pohang | CR16: Tobruk | CS16: Safi | DD16: Manzanillo | DE16: Labuan, Sabah | DF16: Quelimane | DI16: Tin Can Island | DJ16: San Juan Del Sur | DK16: IJmuiden | DL16: Haugesund | DP16: Salaverry | DS16: Iloilo | DU16: Ustka | DX16: Viana Do Castelo | EB16: Tuapse | EC16: Rabigh | EG16: Malmo | ET16: Songkhla | EU16: Tunis | EW16: Istanbul | EX16: Tembladora | FA16: Tanga | FC16: Boston | FF16: Matanzas | FL16: Saldanha Bay
B17: Mina Saqr | F17: Puerto Madryn | H17: Geelong | S17: Paranagua | V17: Nanaimo | Z17: San Antonio | AB17: Ningbo | AI17: Hamburg | AK17: Ronne | AN17: Mostaganem | AR17: Ceuta | AS17: Pori | AW17: Marseille | AY17: Glasgow | BI17: Volos | BP17: Split | BR17: Surabaya, Java (Tanjung Perak) | BS17: New Ross | BU17: Tuticorin | BW17: Khorramshahr | BY17: La Spezia | CB17: Himeji | CI17: Tonghae | CR17: Tripoli | CS17: Tangier | DD17: Mazatlan | DE17: Lahad Datu, Sabah | DI17: Warri | DK17: Rotterdam | DL17: Kristiansand | DP17: Talara | DS17: Jolo | EB17: Vladivostok | EC17: Ras al Mishab | EG17: Solvesborg | ET17: Sriracha | EW17: Trabzon | FC17: Charleston | FF17: Palua
B18: Mina Zayed | F18: Rio Gallegos | H18: Hobart | S18: Porto Alegre | V18: Sept Iles (Seven Islands) | Z18: San Vicente | AB18: Qingdao | AI18: Karlsruhe | AN18: Oran | AR18: Huelva | AS18: Rauma | AW18: Nantes-St. Nazaire | AY18: Grangemouth | BP18: Zadar | BR18: Ujung Pandang, Sulawesi (Makassar) | BS18: Waterford | BU18: Vishakhapatnam | BW18: Lavan | BY18: Livorno | CB18: Hiroshima | CI18: Ulsan | CR18: Zuara | DD18: Progreso | DE18: Lumut | DK18: Terneuzen | DL18: Larvik | DS18: Legaspi, Davao | EB18: Vyborg | EC18: Ras Tanura | EG18: Stockholm | FC18: Chicago | FF18: Puerto Cabello
F19: Rosario | H19: Mackay | S19: Recife | V19: St Johns | Z19: Talcahuano | AB19: Qinhuangdao | AI19: Kiel | AN19: Skikda (Ex Philippeville) | AR19: Las Palmas | AS19: Turku | AW19: Paris | AY19: Hull | BW19: Sirri Island | BY19: Messina | CB19: Kawasaki | CI19: Yosu (Yeosu) | DD19: Salina Cruz | DE19: Miri, Sarawak | DL19: Oslo | DS19: Manila | EC19: Yanbu | EG19: Sundsvall | FC19: Cleveland | FF19: Puerto La Cruz
F20: Santa Fe | H20: Melbourne | S20: Rio De Janeiro | V20: Sydney | Z20: Valparaiso | AB20: Shanghai | AI20: Lubeck | AN20: Tenes | AR20: Malaga | AS20: Uusikaupunki | AW20: Rouen | AY20: Leith | BY20: Milazzo | CB20: Kinuura | DD20: Tampico | DE20: Pasir Gudang, Johor | DL20: Stavanger | DS20: Puerto Princesa,Palawan | FC20: Corpus Christi | FF20: Punta Cardon
F21: Ushuaia | H21: Sydney | S21: Rio Grande | V21: Thunder Bay | AB21: Shantou | AI21: Mannheim | AR21: Pasajes | AS21: Vaasa | AW21: St Malo | AY21: Liverpool | BY21: Napoli (Naples) | CB21: Kobe | DD21: Topolobampo | DE21: Penang (Georgetown) | DL21: Trondheim | DS21: San Fernando, Luzon | FC21: Detroit
H22: Townsville | S22: Salvador | V22: Toronto | AB22: Shenzhen | AI22: Rostock | AR22: Santa Cruz de Tenerife | AW22: Strasbourg | AY22: London | BY22: Palermo | CB22: Kushiro, Hokkaido | DD22: Tuxpan | DE22: Port Dickson | DS22: Subic Bay | FC22: Duluth-Superior
S23: Santos | V23: Trois-Rivieres | AB23: Tianjin | AI23: Wilhelmshavn | AR23: Santander | AW23: Toulon | AY23: Manchester | BY23: Porto Torres | CB23: Mizushima | DD23: Veracruz | DE23: Port Klang (Kelang) | DS23: Zamboanga, Mindanao | FC23: Freeport
S24: Vitoria | V24: Vancouver | AB24: Xiamen | AR24: Tarragona | AY24: Peterhead Bay | BY24: Ravenna | CB24: Moji | DE24: Sandakan, Sabah | FC24: Hampton Roads (Norfolk, Chesapeake)
V25: Windsor | AB25: Yantian | AR25: Valencia | AY25: Plymouth | BY25: Sarroch (Porto Foxi) | CB25: Nagoya | DE25: Sibu, Sarawak | FC25: Honolulu
V26: Alberni | AB26: Zhanjiang | AR26: Vigo | AY26: Portsmouth | BY26: Savona-Vado | CB26: Osaka | DE26: Tanjung Pelepas,Johor | FC26: Houston
V27: Saguenay | AY27: Scapa Flow | BY27: Taranto | CB27: Sakai | DE27: Tawau, Sabah | FC27: Huntington - Tri-State (WV)
AY28: Southampton | BY28: Trieste | CB28: Sakata | FC28: Jacksonville
AY29: Sullom Voe | BY29: Venice | CB29: Shimizu | FC29: Lake Charles
AY30: Teesport | CB30: Tokyo | FC30: Long Beach
AY31: Thamesport | CB31: Tomakomai,Hokkaido | FC31: Los Angeles
AY32: Tyne | CB32: Yokohama | FC32: Manatee
FC33: Memphis
FC34: Miami
FC35: Mobile
FC36: New Orleans
FC37: New York/New Jersey
FC38: Oakland
FC39: Pascagoula
FC40: Philadelphia
FC41: Pittsburgh
...
